<?xml version="1.0"?>
<robot xmlns:xacro="http://www.ros.org/wiki/xacro"  >
<xacro:include filename="inertial_macros.xacro" />

    <material name="white">
        <color rgba="1 1 1 1" />
    </material>
    
    <material name="orange">
        <color rgba="1 0.3 0.1 1" />
    </material>
    
    <material name="blue">
        <color rgba="0.2 0.2 1 1" />
    </material>
    
    <material name="black">
        <color rgba="0 0 0 1" />
    </material>

    <material name="red">
        <color rgba="1 0 0 1" />
    </material>

    <!-- BASE LINK -->

    <link name="base_link" >

    </link>

    <!-- BASE FOOTPRINT LINK -->

    <joint name="base_footprint_joint" type="fixed">
        <parent link="base_link" />
        <child link="base_footprint" />
        <origin xyz="0 0 0" rpy="0 0 0"/>
    </joint>

    <link name="base_footprint"></link>

    <!-- CHASSIS LINK -->

    <joint name="chassis_joint" type="fixed">
        <parent link="base_link"/>
        <child link="chassis"/>
        <origin xyz="-0.275 0 0"/>
    </joint>

    <link name="chassis">
        <visual>
        <origin xyz="0.275 0 0.00625"/>
            <geometry>
                <box size="0.55 0.56 0.0125"/>
            </geometry>
            <material name="white" />
        </visual>
        <collision>
        <origin xyz="0.275 0 0.00625"/>
            <geometry>
                <box size="0.16 0.16 0.0125"/>
            </geometry>
        </collision>
        <xacro:inertial_box mass="0.5" x="0.55" y="0.56" z="0.0125">
            <origin xyz="0.275 0 0.00625" rpy="0 0 0"/>
        </xacro:inertial_box>
    </link>
    
    <gazebo reference="chassis">
        <material>Gazebo/Orange</material>
    </gazebo>

    <!-- LEFT WHEEL LINK-->
    <joint name="left_wheel_joint" type="continuous">
        <parent link="base_link"/>
        <child link="left_wheel"/>
        <origin xyz="0 0.17 -0.02375" rpy="-${pi/2} 0 0"/>
        <axis xyz="0 0 1"/>
    </joint>

    <link name="left_wheel">
        <visual>
            <geometry>
                <cylinder radius="0.0525" length="0.055"/>
            </geometry>
            <material name="blue"/>
        </visual>
        <collision>
            <geometry>
                <cylinder radius="0.0525" length="0.055"/>
            </geometry>
        </collision>
        <xacro:inertial_cylinder mass="0.1" length="0.055" radius="0.0525">
            <origin xyz="0 0 0" rpy="0 0 0"/>
        </xacro:inertial_cylinder>
    </link>

    <gazebo reference="left_wheel">
        <material>Gazebo/Blue</material>
    </gazebo>

    <!-- RIGHT WHEEL LINK-->
    <joint name="right_wheel_joint" type="continuous">
        <parent link="base_link"/>
        <child link="right_wheel"/>
        <origin xyz="0 -0.17 -0.02375" rpy="${pi/2} 0 0"/>
        <axis xyz="0 0 -1"/>
    </joint>

    <link name="right_wheel">
        <visual>
            <geometry>
                <cylinder radius="0.0525" length="0.055"/>
            </geometry>
            <material name="blue"/>
        </visual>
        <collision>
            <geometry>
                <cylinder radius="0.0525" length="0.055"/>
            </geometry>
        </collision>
        <xacro:inertial_cylinder mass="0.1" radius="0.0525" length="0.055">
            <origin xyz="0 0 0" rpy="0 0 0"/>
        </xacro:inertial_cylinder>
    </link>

    <gazebo reference="right_wheel">
        <material>Gazebo/Blue</material>
    </gazebo>

    <!-- CASTER WHEEL TOP-->

    <joint name="caster_wheel_top_joint" type="fixed">
        <parent link="chassis"/>
        <child link="caster_wheel_top"/>
        <origin xyz="0.44 0 -0.02375"/>
    </joint>

    <link name="caster_wheel_top">
        <visual>
            <geometry>
                <sphere radius="0.0525"/>
            </geometry>
            <material name="black"/>
        </visual>
        <collision>
            <geometry>
                <sphere radius="0.0525"/>
            </geometry>
        </collision>
        <xacro:inertial_sphere mass="0.1" radius="0.0525">
            <origin xyz="0 0 0" rpy="0 0 0"/>
        </xacro:inertial_sphere>
    </link>

    <gazebo reference="caster_wheel_top">
        <material>Gazebo/White</material>
        <mu1 value="0.001"/>
        <mu2 value="0.001"/>
    </gazebo>

        <!-- CASTER WHEEL BOTTOM-->

    <joint name="caster_wheel_bottom_joint" type="fixed">
        <parent link="chassis"/>
        <child link="caster_wheel_bottom"/>
        <origin xyz="0.105 0 -0.02375"/>
    </joint>

    <link name="caster_wheel_bottom">
        <visual>
            <geometry>
                <sphere radius="0.0525"/>
            </geometry>
            <material name="black"/>
        </visual>
        <collision>
            <geometry>
                <sphere radius="0.0525"/>
            </geometry>
        </collision>
        <xacro:inertial_sphere mass="0.1" radius="0.0525">
            <origin xyz="0 0 0" rpy="0 0 0"/>
        </xacro:inertial_sphere>
    </link>

    <gazebo reference="caster_wheel_bottom">
        <material>Gazebo/White</material>
        <mu1 value="0.001"/>
        <mu2 value="0.001"/>
    </gazebo>

        <!--   PROJECT BOX -->

    <joint name="project_box_joint" type="fixed">
        <parent link="chassis"/>
        <child link="project_box"/>
        <origin xyz="0.27 0 0.06"/>
    </joint>

    <link name="project_box">
        <visual> 
            <geometry>
                <box size="0.19 0.19 0.095"/>
            </geometry>
            <material name="white"/>
        </visual>
        <collision>
            <geometry>
                <box size="0.19 0.19 0.095"/>
            </geometry>
        </collision>
        <xacro:inertial_box mass="0.5" x="0.19" y="0.19" z="0.095">
            <origin xyz="0 0 0" rpy="0 0 0"/>
        </xacro:inertial_box>
    </link>

    <gazebo reference="project_box">
        <material>Gazebo/Orange</material>
    </gazebo>

            <!--   LEG 1 -->

    <joint name="leg1_joint" type="fixed">
        <parent link="chassis"/>
        <child link="leg1"/>
        <origin xyz="0.525 -0.255 0.2125"/>
    </joint>

    <link name="leg1">
        <visual> 
            <geometry>
                <box size="0.05 0.05 0.4"/>
            </geometry>
            <material name="white"/>
        </visual>
        <collision>
            <geometry>
                <box size="0.05 0.05 0.4"/>
            </geometry>
        </collision>
        <xacro:inertial_box mass="0.5" x="0.05" y="0.05" z="0.4">
            <origin xyz="0 0 0" rpy="0 0 0"/>
        </xacro:inertial_box>
    </link>

    <gazebo reference="leg1">
        <material>Gazebo/Orange</material>
    </gazebo>

                 <!--   LEG 2 -->

    <joint name="leg2_joint" type="fixed">
        <parent link="chassis"/>
        <child link="leg2"/>
        <origin xyz="0.525 0.255 0.2125"/>
    </joint>

    <link name="leg2">
        <visual> 
            <geometry>
                <box size="0.05 0.05 0.4"/>
            </geometry>
            <material name="white"/>
        </visual>
        <collision>
            <geometry>
                <box size="0.05 0.05 0.4"/>
            </geometry>
        </collision>
        <xacro:inertial_box mass="0.5" x="0.05" y="0.05" z="0.4">
            <origin xyz="0 0 0" rpy="0 0 0"/>
        </xacro:inertial_box>
    </link>

    <gazebo reference="leg2">
        <material>Gazebo/Orange</material>
    </gazebo>

             <!--   LEG 3 -->

    <joint name="leg3_joint" type="fixed">
        <parent link="chassis"/>
        <child link="leg3"/>
        <origin xyz="0.025 -0.255 0.2125"/>
    </joint>

    <link name="leg3">
        <visual> 
            <geometry>
                <box size="0.05 0.05 0.4"/>
            </geometry>
            <material name="white"/>
        </visual>
        <collision>
            <geometry>
                <box size="0.05 0.05 0.4"/>
            </geometry>
        </collision>
        <xacro:inertial_box mass="0.5" x="0.05" y="0.05" z="0.4">
            <origin xyz="0 0 0" rpy="0 0 0"/>
        </xacro:inertial_box>
    </link>

    <gazebo reference="leg3">
        <material>Gazebo/Orange</material>
    </gazebo>

                 <!--   LEG 4 -->

    <joint name="leg4_joint" type="fixed">
        <parent link="chassis"/>
        <child link="leg4"/>
        <origin xyz="0.025 0.255 0.2125"/>
    </joint>

    <link name="leg4">
        <visual> 
            <geometry>
                <box size="0.05 0.05 0.4"/>
            </geometry>
            <material name="white"/>
        </visual>
        <collision>
            <geometry>
                <box size="0.05 0.05 0.4"/>
            </geometry>
        </collision>
        <xacro:inertial_box mass="0.5" x="0.05" y="0.05" z="0.4">
            <origin xyz="0 0 0" rpy="0 0 0"/>
        </xacro:inertial_box>
    </link>

    <gazebo reference="leg4">
        <material>Gazebo/Orange</material>
    </gazebo>

                 <!--   TABLE TOP -->

    <joint name="table_top_joint" type="fixed">
        <parent link="chassis"/>
        <child link="table_top"/>
        <origin xyz="0.275 0 0.43125"/>
    </joint>

    <link name="table_top">
        <visual> 
            <geometry>
                <box size="0.55 0.56 0.05"/>
            </geometry>
            <material name="white"/>
        </visual>
        <collision>
            <geometry>
                <box size="0.55 0.56 0.05"/>
            </geometry>
        </collision>
        <xacro:inertial_box mass="0.5" x="0.55" y="0.56" z="0.05">
            <origin xyz="0 0 0  " rpy="0 0 0"/>
        </xacro:inertial_box>
    </link>

    <gazebo reference="table_top">
        <material>Gazebo/Orange</material>
    </gazebo>



</robot>